<?xml version="1.0"?>
<robot xmlns:xacro="http://www.ros.org/wiki/xacro" name="my_robot"> 
   
    <material  name="white">
        <color rgba="1 1 1 1"/>
    </material>

    <material  name="Blue">
        <color rgba="0.2 0.2 1 1"/>
    </material>

    <material  name="Red">
        <color rgba="0.8 0.0 0.0 1.0"/>
    </material>

    <material  name="Black">
        <color rgba="0 0 0 1"/>
    </material>



    <!-- CHASSIS LINK -->

    <link name="chassis">
        <inertial>
            <origin xyz="0.0 0.0 0.0"/>
            <mass value="1.0"/>
            <inertia ixx="0.1" ixy="0.0" ixz="0.0" iyy="0.1" iyz="0.0" izz="0.1"/>
        </inertial>
        <visual>
            <origin xyz="0.0 0.0 0.2" />
            <geometry>
                <box size="0.6 0.45 0.15"/>
            </geometry>
            <material name="white"/>
        </visual>
        <collision>
            <origin xyz="0.0 0.0 0.2" rpy="0.0 0.0 0.0"/>
            <geometry>
                <box size="0.6 0.45 0.15"/>
            </geometry>
        </collision>
    </link>

    <joint name="chassis_joint" type="fixed">
        <parent link="base_link"/>
        <child link="chassis"/>
        <axis xyz="-0.1 0.0 0.1"/>
    </joint>
    

    <!-- FRIST RIGHT WHEEL LINK --> 

    <link name="frist_right_wheel">
        <inertial>
            <origin xyz="0.0 0.0 0.0" rpy="0.0 0.0 0.0"/>
            <mass value="0.0"/>
            <inertia ixx="0.0" ixy="0.0" ixz="0.0" iyy="0.0" iyz="0.0" izz="0.0"/>
        </inertial>
        <visual >
            <origin  rpy="0 1.5707 1.5707"/>
            <geometry>
                <cylinder radius="0.1" length="0.03"/> 
            </geometry>
            <material name="Black"/>
        </visual>
        <collision>
            <origin xrpy="0 1.5707 1.5707"/>
            <geometry>
                <cylinder radius=".1" length="0.03"/>
            </geometry>
        </collision>
    </link>

    <joint name="frist_right_wheel_joint" type="revolute">
        <origin xyz="0.175 0.24 0.10" rpy="0.0 0.0 0.0"/>
        <parent link="chassis"/>
        <child link="frist_right_wheel"/>
        <axis xyz="0 0 0"/>
    </joint>


        <!-- SECOND RIGHT WHEEL LINK --> 
        
    <link name="second_right_wheel">
        <inertial>
            <origin rpy="0.0 0.0 0.0"/>
            <mass value="0.0"/>
            <inertia ixx="0.0" ixy="0.0" ixz="0.0" iyy="0.0" iyz="0.0" izz="0.0"/>
        </inertial>
        <visual >
            <origin  rpy="0 1.5707 1.5707"/>
            <geometry>
                <cylinder radius="0.1" length="0.03"/> 
            </geometry>
            <material name="Black"/>
        </visual>
        <collision>
            <origin  rpy="0 1.5707 1.5707"/>
            <geometry>
                <cylinder radius=".1" length="0.03"/>
            </geometry>
        </collision>
    </link>

    <joint name="second_right_wheel_joint" type="revolute">
        <origin xyz="-0.175 0.24 0.10" rpy="0.0 0.0 0.0"/>
        <parent link="chassis"/>
        <child link="second_right_wheel"/>
        <axis xyz="0 0 0"/>
    </joint>


    <!-- FRIST LEFT WHEEL LINK --> 

    <link name="frist_left_wheel">
        <inertial>
            <origin xyz="0.0 0.0 0.0" rpy="0.0 0.0 0.0"/>
            <mass value="0.0"/>
            <inertia ixx="0.0" ixy="0.0" ixz="0.0" iyy="0.0" iyz="0.0" izz="0.0"/>
        </inertial>
        <visual >
            <origin  rpy="0 1.5707 1.5707"/>
            <geometry>
                <cylinder radius="0.1" length="0.03"/> 
            </geometry>
            <material name="Black"/>
        </visual>
        <collision>
            <origin rpy="0 1.5707 1.5707"/>
            <geometry>
                <cylinder radius=".1" length="0.03"/>
            </geometry>
        </collision>
    </link>

    <joint name="frist_left_wheel_joint" type="revolute">
        <origin xyz="0.175 -0.24 0.10" rpy="0.0 0.0 0.0"/>
        <parent link="chassis"/>
        <child link="frist_left_wheel"/>
        <axis xyz="0 0 0"/>
    </joint>


    <!-- SECOND LEFT WHEEL LINK --> 

    <link name="second_left_wheel">
        <inertial>
            <origin xyz="0.0 0.0 0.0" rpy="0.0 0.0 0.0"/>
            <mass value="0.0"/>
            <inertia ixx="0.0" ixy="0.0" ixz="0.0" iyy="0.0" iyz="0.0" izz="0.0"/>
        </inertial>
        <visual >
            <origin rpy="0 1.5707 1.5707"/>
            <geometry>
                <cylinder radius="0.1" length="0.03"/> 
            </geometry>
            <material name="Black"/>
        </visual>
        <collision>
            <origin rpy="0 1.5707 1.5707"/>
            <geometry>
                <cylinder radius=".1" length="0.03"/>
            </geometry>
        </collision>
    </link>

    <joint name="second_left_wheel_joint" type="revolute">
        <origin xyz="-0.175 -0.24 0.10" rpy="0.0 0.0 0.0"/>
        <parent link="chassis"/>
        <child link="second_left_wheel"/>
        <axis xyz="0 0 0"/>
    </joint>

    <!-- CAMERA LINK -->
    <link name="camera">
        <inertial>
            <origin xyz="0.0 0.0 0.0" rpy="0.0 0.0 0.0"/>
            <mass value="0.0"/>
            <inertia ixx="0.0" ixy="0.0" ixz="0.0" iyy="0.0" iyz="0.0" izz="0.0"/>
        </inertial>
        <visual >
            <origin xyz="0.0 0.0 0.0" rpy="0.0 0.0 0.0"/>
            <geometry>
                <box size="0.050 0.20 0.07"/>
            </geometry>
            <material name="Blue"/>
        </visual>
        <collision>
            <origin xyz="0.0 0.0 0.0" rpy="0.0 0.0 0.0"/>
            <geometry>
                <box size="0.0 0.0 0.0"/>
            </geometry>
        </collision>
    </link>

    <joint name="camera_link_joint" type="fixed">
        <origin xyz="0.325 0.0 0.2" rpy="0.0 0.0 0.0"/>
        <parent link="chassis"/>
        <child link="camera"/>
        <axis xyz="0.0 0.0 0.0"/>
    </joint>


    <!-- LIDAR LINK -->
    
    
    <!-- LIDER BOX LINK -->
    
     <link name="lider_box">
        <inertial>
            <origin xyz="0.0 0.0 0.0" rpy="0.0 0.0 0.0"/>
            <mass value="0.0"/>
            <inertia ixx="0.0" ixy="0.0" ixz="0.0" iyy="0.0" iyz="0.0" izz="0.0"/>
        </inertial>
        <visual name="Box">
            <origin xyz="0.0 0.0 0.0" rpy="0.0 0.0 0.0"/>
            <geometry>
                <box size="0.2 0.12 0.06"/>
            </geometry>
            <material name="Red"/>

        </visual>
        <collision>
            <origin xyz="0.0 0.0 0.0" rpy="0.0 0.0 0.0"/>
            <geometry>
                <box size="0.2 0.12 0.06"/>
            </geometry>
        </collision>
     </link>

    <joint name="lider_box_joint" type="fixed">
        <origin xyz="0.0 0.0 0.304" rpy="0.0 0.0 0.0"/>
        <parent link="chassis"/>
        <child link="lider_box"/>
        <axis xyz="0.0 0.0 0.0"/>
    </joint>


    <!-- LIDER CYLINDER LINK-->
    
    <link name="lider_cylinder">
        <inertial>
            <origin xyz="0.0 0.0 0.0" rpy="0.0 0.0 0.0"/>
            <mass value="0.0"/>
            <inertia ixx="0.0" ixy="0.0" ixz="0.0" iyy="0.0" iyz="0.0" izz="0.0"/>
        </inertial>
        <visual name="">
            <geometry>
                <cylinder radius="0.06" length="0.07"/>
            </geometry>
            <material name="Red"/>
        </visual>
        <collision>
            <geometry>
                <cylinder radius="0.06" length="0.07"/>
            </geometry>
        </collision>
    </link>

    <joint name="lider_cylinder_joiny" type="fixed">
        <origin xyz="-0.04 0.0 0.365" rpy="0.0 0.0 0.0"/>
        <parent link="chassis"/>
        <child link="lider_cylinder"/>
        <axis xyz="0.0 0.0 0.0"/>
    </joint>

</robot>
